<?xml version="1.0"?>
<robot xmlns:xacro="http://ros.org/wiki/xacro" name="simple_bot">

  
  <xacro:property name="body_length" value="0.56"/>
  <xacro:property name="body_width" value="0.59"/>
  <xacro:property name="body_height" value="0.1"/>
  <xacro:property name="wheel_radius" value="0.05"/>
  <xacro:property name="wheel_width" value="0.04"/>

  
  <material name="white"><color rgba="1 1 1 1"/></material>
  <material name="black"><color rgba="0 0 0 1"/></material>

  
  <link name="base">
    <visual>
      <origin xyz="0 0 ${wheel_radius}" rpy="0 0 0"/>
      <geometry>
        <box size="${body_length} ${body_width} ${body_height}"/>
      </geometry>
      <material name="white"/>
    </visual>
    <collision>
      <origin xyz="0 0 ${wheel_radius}" rpy="0 0 0"/>
      <geometry>
        <box size="${body_length} ${body_width} ${body_height}"/>
      </geometry>
    </collision>
    <inertial>
      <mass value="1.0"/>
      <inertia ixx="0.1" iyy="0.1" izz="0.1" ixy="0" ixz="0" iyz="0"/>
    </inertial>
  </link>

  
  <xacro:macro name="wheel" params="name x y">
    <link name="${name}">
      <visual>
        <origin xyz="${x} ${y} ${wheel_radius}" rpy="0 1.57 0"/>
        <geometry>
          <cylinder radius="${wheel_radius}" length="${wheel_width}"/>
        </geometry>
        <material name="black"/>
      </visual>
      <collision>
        <origin xyz="${x} ${y} ${wheel_radius}" rpy="0 1.57 0"/>
        <geometry>
          <cylinder radius="${wheel_radius}" length="${wheel_width}"/>
        </geometry>
      </collision>
      <inertial>
        <mass value="0.2"/>
        <inertia ixx="0.01" iyy="0.01" izz="0.01" ixy="0" ixz="0" iyz="0"/>
      </inertial>
    </link>
    <joint name="joint_${name}" type="continuous">
      <parent link="base"/>
      <child link="${name}"/>
      <origin xyz="${x} ${y} 0" rpy="0 0 0"/>
      <axis xyz="0 1 0"/>
    </joint>
  </xacro:macro>

  
  <xacro:wheel name="front_left"  x="0.15" y=" 0.15"/>
  <xacro:wheel name="front_right" x="0.15" y="-0.15"/>
  <xacro:wheel name="rear_left"   x="-0.15" y=" 0.15"/>
  <xacro:wheel name="rear_right"  x="-0.15" y="-0.15"/>

  
  <link name="lidar">
    <visual>
      <origin xyz="0 0 ${body_height}" rpy="0 0 0"/>
      <geometry>
        <cylinder radius="0.05" length="0.02"/>
      </geometry>
      <material name="black"/>
    </visual>
  </link>
  <joint name="joint_lidar" type="fixed">
    <parent link="base"/>
    <child link="lidar"/>
    <origin xyz="0 0 0.2" rpy="0 0 0"/>
  </joint>

  
  <gazebo reference="lidar">
    <sensor type="ray" name="lidar_sensor">
      <pose>0 0 0 0 0 0</pose>
      <visualize>true</visualize>
      <update_rate>20</update_rate>
      <ray>
        <scan>
          <horizontal>
            <samples>360</samples>
            <resolution>1</resolution>
            <min_angle>-1.57</min_angle>
            <max_angle>1.57</max_angle>
          </horizontal>
        </scan>
        <range>
          <min>0.12</min>
          <max>3.5</max>
          <resolution>0.01</resolution>
        </range>
        <noise>
          <type>gaussian</type>
          <mean>0.0</mean>
          <stddev>0.01</stddev>
        </noise>
      </ray>
      <plugin name="gazebo_ros_laser" filename="libgazebo_ros_ray_sensor.so">
        <ros>
          <remapping>~/out:=scan</remapping>
        </ros>
        <output_type>sensor_msgs/LaserScan</output_type>
        <frame_name>lidar</frame_name>
      </plugin>
    </sensor>
  </gazebo>

  
  <gazebo reference="base">
    <plugin name="diff_drive_controller" filename="libgazebo_ros_diff_drive.so">
      <ros>
        <remapping>cmd_vel:=/cmd_vel</remapping>
      </ros>
      <update_rate>50.0</update_rate>
      <left_joint>joint_rear_left</left_joint>
      <right_joint>joint_rear_right</right_joint>
      <wheel_separation>0.3</wheel_separation>
      <wheel_radius>0.05</wheel_radius>
      <command_topic>/cmd_vel</command_topic>
      <odometry_topic>odom</odometry_topic>
      <odom_frame>odom</odom_frame>
      <base_frame>base</base_frame>
      <publish_odom>true</publish_odom>
      <publish_odom_tf>true</publish_odom_tf>
    </plugin>
  </gazebo>

</robot>
